[*] Running ...
[*] Dataset loaded: E:\Coding\pythonProject\llm4contract\problems\dataset\train_01.pkl with 5 instances.
Traceback (most recent call last):
  File "E:\Coding\pythonProject\llm4contract\problems\eval.py", line 149, in <module>
    _p, _c, _v, _contract_logs = extract_data(_dataset_path)
  File "E:\Coding\pythonProject\llm4contract\problems\eval.py", line 128, in extract_data
    p, c = extract_contract_elements(agent_setting)
  File "E:\Coding\pythonProject\llm4contract\utils\utils.py", line 127, in extract_contract_elements
    p = np.array(agent_setting[[f'p{i}' for i in range(agent_setting.shape[1]-1)]])
  File "D:\Software\anaconda3\envs\llm4contract\lib\site-packages\pandas\core\frame.py", line 4108, in __getitem__
    indexer = self.columns._get_indexer_strict(key, "columns")[1]
  File "D:\Software\anaconda3\envs\llm4contract\lib\site-packages\pandas\core\indexes\base.py", line 6200, in _get_indexer_strict
    self._raise_if_missing(keyarr, indexer, axis_name)
  File "D:\Software\anaconda3\envs\llm4contract\lib\site-packages\pandas\core\indexes\base.py", line 6249, in _raise_if_missing
    raise KeyError(f"None of [{key}] are in the [{axis_name}]")
KeyError: "None of [Index(['p0', 'p1', 'p2', 'p3', 'p4'], dtype='object')] are in the [columns]"
